[2021-08-23 23:21:09 +0800] [29409] [INFO] Starting gunicorn 20.1.0
[2021-08-23 23:21:09 +0800] [29409] [INFO] Listening at: http://0.0.0.0:8080 (29409)
[2021-08-23 23:21:09 +0800] [29409] [INFO] Using worker: sync
[2021-08-23 23:21:09 +0800] [29412] [INFO] Booting worker with pid: 29412
[2021-08-23 23:21:09 +0800] [29412] [ERROR] Exception in worker process
Traceback (most recent call last):
  File "/usr/local/lib/python3.6/dist-packages/gunicorn/arbiter.py", line 589, in spawn_worker
    worker.init_process()
  File "/usr/local/lib/python3.6/dist-packages/gunicorn/workers/base.py", line 134, in init_process
    self.load_wsgi()
  File "/usr/local/lib/python3.6/dist-packages/gunicorn/workers/base.py", line 146, in load_wsgi
    self.wsgi = self.app.wsgi()
  File "/usr/local/lib/python3.6/dist-packages/gunicorn/app/base.py", line 67, in wsgi
    self.callable = self.load()
  File "/usr/local/lib/python3.6/dist-packages/gunicorn/app/wsgiapp.py", line 58, in load
    return self.load_wsgiapp()
  File "/usr/local/lib/python3.6/dist-packages/gunicorn/app/wsgiapp.py", line 48, in load_wsgiapp
    return util.import_app(self.app_uri)
  File "/usr/local/lib/python3.6/dist-packages/gunicorn/util.py", line 359, in import_app
    mod = importlib.import_module(module)
  File "/usr/lib/python3.6/importlib/__init__.py", line 126, in import_module
    return _bootstrap._gcd_import(name[level:], package, level)
  File "<frozen importlib._bootstrap>", line 994, in _gcd_import
  File "<frozen importlib._bootstrap>", line 971, in _find_and_load
  File "<frozen importlib._bootstrap>", line 955, in _find_and_load_unlocked
  File "<frozen importlib._bootstrap>", line 665, in _load_unlocked
  File "<frozen importlib._bootstrap_external>", line 678, in exec_module
  File "<frozen importlib._bootstrap>", line 219, in _call_with_frames_removed
  File "/usr/Cinema_Tickets_Booking_System/Server/user_login.py", line 1, in <module>
    from flask import Flask, redirect, url_for, request
ModuleNotFoundError: No module named 'flask'
[2021-08-23 23:21:09 +0800] [29412] [INFO] Worker exiting (pid: 29412)
[2021-08-23 23:21:09 +0800] [29409] [INFO] Shutting down: Master
[2021-08-23 23:21:09 +0800] [29409] [INFO] Reason: Worker failed to boot.
1
[2021-08-29 20:43:15 +0800] [10456] [INFO] Starting gunicorn 20.1.0
[2021-08-29 20:43:15 +0800] [10456] [INFO] Listening at: http://0.0.0.0:8080 (10456)
[2021-08-29 20:43:15 +0800] [10456] [INFO] Using worker: sync
[2021-08-29 20:43:15 +0800] [10459] [INFO] Booting worker with pid: 10459
[2021-08-29 20:43:15 +0800] [10460] [INFO] Booting worker with pid: 10460
[2021-08-29 20:43:15 +0800] [10461] [INFO] Booting worker with pid: 10461
[2021-08-29 20:43:15 +0800] [10462] [INFO] Booting worker with pid: 10462
[2021-08-29 20:52:18 +0800] [10461] [INFO] Parent changed, shutting down: <Worker 10461>
[2021-08-29 20:52:18 +0800] [10461] [INFO] Worker exiting (pid: 10461)
[2021-08-29 20:52:22 +0800] [10459] [INFO] Parent changed, shutting down: <Worker 10459>
[2021-08-29 20:52:22 +0800] [10459] [INFO] Worker exiting (pid: 10459)
getMvRank request accepted!
its json!
number is : 6
number of result is: 6
result is : 1
[2021-08-29 20:52:22 +0800] [10462] [INFO] Parent changed, shutting down: <Worker 10462>
[2021-08-29 20:52:22 +0800] [10462] [INFO] Worker exiting (pid: 10462)
result is : 1
result is : -2
[2021-08-29 20:52:30 +0800] [10460] [INFO] Parent changed, shutting down: <Worker 10460>
[2021-08-29 20:52:30 +0800] [10460] [INFO] Worker exiting (pid: 10460)
result is : 1
result is : -2
[2021-08-29 22:56:46 +0800] [11695] [INFO] Starting gunicorn 20.1.0
[2021-08-29 22:56:46 +0800] [11695] [INFO] Listening at: http://0.0.0.0:8080 (11695)
[2021-08-29 22:56:46 +0800] [11695] [INFO] Using worker: sync
[2021-08-29 22:56:46 +0800] [11698] [INFO] Booting worker with pid: 11698
[2021-08-29 22:56:46 +0800] [11699] [INFO] Booting worker with pid: 11699
[2021-08-29 22:56:46 +0800] [11701] [INFO] Booting worker with pid: 11701
[2021-08-29 22:56:46 +0800] [11702] [INFO] Booting worker with pid: 11702
[2021-08-29 23:00:52,746] ERROR in app: Exception on /userTickets [POST]
Traceback (most recent call last):
  File "/usr/lib/python3.6/site-packages/flask/app.py", line 2070, in wsgi_app
    response = self.full_dispatch_request()
  File "/usr/lib/python3.6/site-packages/flask/app.py", line 1515, in full_dispatch_request
    rv = self.handle_user_exception(e)
  File "/usr/lib/python3.6/site-packages/flask_cors/extension.py", line 165, in wrapped_function
    return cors_after_request(app.make_response(f(*args, **kwargs)))
  File "/usr/lib/python3.6/site-packages/flask/app.py", line 1513, in full_dispatch_request
    rv = self.dispatch_request()
  File "/usr/lib/python3.6/site-packages/flask/app.py", line 1499, in dispatch_request
    return self.ensure_sync(self.view_functions[rule.endpoint])(**req.view_args)
  File "/usr/Cinema_Tickets_Booking_System/Server/user_login.py", line 163, in userTickets
    result=(getUserTickets(userid))
  File "/usr/Cinema_Tickets_Booking_System/Server/database.py", line 84, in getUserTickets
    db.execute('SELECT cinema_id,hall_id,mv_name,start_time FROM cinema_info WHERE cinema_id=%s',(temp[i]['film_id'],))
  File "/usr/lib/python3.6/site-packages/pymysql/cursors.py", line 148, in execute
    result = self._query(query)
  File "/usr/lib/python3.6/site-packages/pymysql/cursors.py", line 310, in _query
    conn.query(q)
  File "/usr/lib/python3.6/site-packages/pymysql/connections.py", line 548, in query
    self._affected_rows = self._read_query_result(unbuffered=unbuffered)
  File "/usr/lib/python3.6/site-packages/pymysql/connections.py", line 775, in _read_query_result
    result.read()
  File "/usr/lib/python3.6/site-packages/pymysql/connections.py", line 1156, in read
    first_packet = self.connection._read_packet()
  File "/usr/lib/python3.6/site-packages/pymysql/connections.py", line 725, in _read_packet
    packet.raise_for_error()
  File "/usr/lib/python3.6/site-packages/pymysql/protocol.py", line 221, in raise_for_error
    err.raise_mysql_exception(self._data)
  File "/usr/lib/python3.6/site-packages/pymysql/err.py", line 143, in raise_mysql_exception
    raise errorclass(errno, errval)
pymysql.err.OperationalError: (1054, "Unknown column 'hall_id' in 'field list'")
[2021-08-29 23:01:21 +0800] [11701] [INFO] Parent changed, shutting down: <Worker 11701>
[2021-08-29 23:01:21 +0800] [11701] [INFO] Worker exiting (pid: 11701)
()
()
getMvRank request accepted!
its json!
number is : 6
number of result is: 6
[2021-08-29 23:01:28 +0800] [11699] [INFO] Parent changed, shutting down: <Worker 11699>
[2021-08-29 23:01:28 +0800] [11699] [INFO] Worker exiting (pid: 11699)
()
getMvRank request accepted!
its json!
number is : 6
number of result is: 6
login request accpted!
its not json
userid is:  lxh123
login success!
[2021-08-29 23:01:29 +0800] [11702] [INFO] Parent changed, shutting down: <Worker 11702>
[2021-08-29 23:01:29 +0800] [11702] [INFO] Worker exiting (pid: 11702)
[{'row': 3, 'col': 6}, {'row': 4, 'col': 3}]
login request accpted!
its not json
userid is:  lxh123
login success!
[2021-08-29 23:01:29 +0800] [11698] [INFO] Parent changed, shutting down: <Worker 11698>
[2021-08-29 23:01:29 +0800] [11698] [INFO] Worker exiting (pid: 11698)
result is : 1
1
getMvRank request accepted!
its json!
number is : 6
number of result is: 6
